File: chosen material tensile test data.csv
"File Path: \\cet-students.main.ad.rit.edu\students\ag8087\Desktop\111 final data\Test Run 1 04-13-22 12 52 16 PM\DAQ- Crosshead, … - (Timed).csv   "
"Test: MCET111 round - Tension (Extensometer-Crosshead) 48"
"Test Run: Test Run 1"
"Date: 4/13/2022 12:29:17 PM"
""
""
"Crosshead ","Load ","Extensometer "
"in","lbf","in"
"0.000635997757066305","226.63067216151","4.57899743668972E-05"
"0.00165359413972689","346.432310194024","8.78252663595078E-05"
"0.00265301924792859","445.295363464372","0.000111043636648027"
"0.00366152999335973","554.219412770872","0.000140220011839635"
"0.00467004073879088","659.805795708286","0.000169952960191505"
"0.00567855148422202","563.760126488637","0.000144830004157527"
"0.00666889066873925","694.202003082508","0.000188785301232445"
"0.00767740141417039","801.228842736634","0.000228509165255644"
"0.00868591215960153","884.010729428403","0.000259966080508508"
"0.00969442290503268","944.56781520095","0.000280222174633381"
"0.0106847620895499","994.877158738883","0.000296785791882811"
"0.0116841876274341","1044.99945421088","0.000313556426597528"
"0.0126926983728653","1098.67116236604","0.000334004159133577"
"0.0137012091182964","1151.73419591696","0.000354528876457374"
"0.0147006335103606","1204.67790948685","0.000374888667301"
"0.0157000590482448","1255.69351315169","0.000396106820624582"
"0.0167085697936759","1306.79363971018","0.000418321801625434"
"0.017726165746654","1353.51789531762","0.00043746874189668"
"0.0187346764920851","1397.968485086","0.000452081457203929"
"0.0197250156766024","1441.88910533421","0.000467690248244009"
"0.0207335275678536","1489.2007401675","0.000486068414844111"
"0.0217329531057378","1534.30962057638","0.000500325066556303"
"0.0227414627053489","1578.30411602904","0.000517947242540714"
"0.0237318018898661","1622.34438556826","0.000531274240278808"
"0.0247312274277504","1669.17632553761","0.000549434378798629"
"0.0257488233807284","1716.38795990842","0.000565641753418613"
"0.0267664193337065","1761.73569981935","0.00058276803994929"
"0.0277658448715907","1806.25259066273","0.000597037116648156"
"0.0287470999943811","1851.33282110377","0.000614630647130149"
"0.0297556095939922","1899.26849834015","0.000635009487232883"
"0.0307641214852434","1946.48101087089","0.000650195542271029"
"0.0317635447314874","1991.37957197559","0.000664395762343458"
"0.0327538839160047","2036.92906913135","0.000682832508996004"
"0.0337533094538889","2084.99493357794","0.00069827171866177"
"0.0347618213451401","2133.21096337324","0.000714709653769341"
"0.0357703309447512","2180.01491199469","0.000731950665537202"
"0.0367606701292684","2225.35694386605","0.000747585667211995"
"0.0377600956671527","2273.94860657311","0.000765883125109033"
"0.0387595189133967","2323.67111973516","0.000783763504490865"
"0.0397589444512809","2371.47968332109","0.000801974452970601"
"0.0407674586341724","2419.22809295155","0.000814309564380591"
"0.0417487114653226","2466.05245879147","0.000832678779261187"
"0.0427481370032068","2516.22063812001","0.000853200059124694"
"0.0437566466028179","2567.61758273618","0.000869490040212276"
"0.0447560721407021","2616.00726865843","0.000885292832917482"
"0.0457554976785863","2663.66961861535","0.000903904818431071"
"0.0467367505097366","2714.52649487212","0.000923582201793343"
"0.0477361760476208","2766.4966583852","0.000937787291601183"
"0.0487446856472319","2815.82904899658","0.000957444694725518"
"0.0497350271233893","2864.56977935243","0.000974435201574733"
"0.0507253640162663","2914.54256809567","0.000991355168874244"
"0.0517247895541506","2965.28177092129","0.00100818941450777"
"0.0527332991537616","3018.91999922897","0.00102945698132302"
"0.0537327246916458","3068.27785647843","0.0010436915043846"
"0.0547139775227961","3117.91123640718","0.00106323969653096"
"0.0557043189989535","3169.85395742232","0.00108042234308765"
"0.0567128285985645","3224.0056897514","0.0010989231124381"
"0.0577213381981756","3277.25489320832","0.00111790441009161"
"0.058711679674333","3326.79123646437","0.00113652606346226"
"0.0597111052122172","3379.81760683804","0.00115368364520433"
"0.0607014421050943","3431.91795756134","0.00117141198858208"
"0.0617099562879857","3486.38077804703","0.00119183422662098"
"0.0627184658875968","3537.20055204659","0.00120892499272866"
"0.0637088027804738","3589.1902546182","0.00122577814439378"
"0.0646991442566312","3644.07283555233","0.00124999018240258"
"0.0657076538562423","3699.11963239412","0.00126735121882557"
"0.0667161634558533","3753.0491902599","0.00128671056549725"
"0.0677065049320107","3803.91484811601","0.00130642325444125"
"0.068705930469895","3859.32893535019","0.00132486207789272"
"0.069696267362772","3914.26530358028","0.00134425264816203"
"0.0707047815456634","3970.48861519362","0.00136394843625961"
"0.0717042070835477","4021.53210043637","0.00138000295131731"
"0.0726945439764247","4075.1788908034","0.00140166697188603"
"0.0736848854525821","4130.85598693781","0.00142275063457576"
"0.0746933950521932","4187.86525169207","0.00144206586717371"
"0.0756928205900774","4241.97922314398","0.0014613435741635"
"0.0766831574829545","4295.82008685643","0.00148015650787655"
"0.0776825876041191","4351.44449339479","0.00150107488601733"
"0.0786820085587229","4409.31698936416","0.00152238513463118"
"0.0796905227416144","4466.37499199475","0.00154322158663504"
"0.0806899436962182","4519.60070467344","0.00156228889240957"
"0.0816711965273684","4575.53290626867","0.00158064607617915"
"0.0826706266485331","4633.67148469803","0.00160453399032809"
"0.0836973089548781","4693.83641717506","0.00162310042949283"
"0.084696729909482","4748.61998557664","0.00164372748287402"
"0.0856961600306466","4803.84351210514","0.00166498359148831"
"0.0866774128617968","4861.31293266481","0.00168359013435643"
"0.0876859178781275","4922.37183195463","0.00170579884915363"
"0.0886762639375653","4978.24256235448","0.00172618499385948"
"0.0896847689538959","5035.04062964461","0.00174662599470246"
"0.0906660217850462","5092.69051207071","0.00176747562363744"
"0.0916654519062108","5154.21966600518","0.00179131197588203"
"0.092683050150829","5212.10357805369","0.00181143486842066"
"0.0936733870437061","5267.82633850466","0.0018305438534012"
"0.0946637239365831","5325.24306946829","0.00185024923774208"
"0.0956540608294602","5386.22029988425","0.00187492404384245"
"0.0966716590740784","5448.00060755984","0.00189649854721611"
"0.097671089195243","5504.42238331826","0.00191647090763954"
"0.0986614260881201","5560.74273160431","0.00193498836299515"
"0.0996517629809971","5618.12828789028","0.00195581808330594"
"0.100660277163889","5680.678302748","0.00198021545771539"
"0.101659698118492","5738.81117313779","0.00199978663787744"
"0.102668212301384","5795.74755061753","0.00202284626732397"
"0.103649465132534","5851.7363935285","0.00204160663654008"
"0.104657979315425","5914.35007498144","0.00206285443795867"
"0.105666484331756","5974.46714774207","0.00208769166405775"
"0.106674998514648","6031.70341683926","0.00210627887121174"
"0.107665335407525","6087.9693192094","0.00212822562288933"
"0.108655672300402","6146.73358659172","0.00214958113139701"
"0.109664186483293","6210.04496611221","0.00217220305756658"
"0.110663607437897","6266.99978495056","0.0021927948769798"
"0.111663037559062","6322.69444428365","0.00221507033579763"
"0.112644290390212","6379.33180830586","0.00223696022615291"
"0.113643711344816","6440.8201278034","0.00225711319646908"
"0.11464314146598","6500.72424678004","0.00227790825572195"
"0.115660739710598","6560.36974765611","0.00229890068248648"
"0.116641992541749","6616.9131485654","0.00231950711110592"
"0.117641413496353","6676.81068134252","0.0023408069041114"
"0.118640843617517","6737.06782061262","0.00236265497203315"
"0.119640264572121","6794.76248919535","0.00238602869941369"
"0.120630601464998","6849.63826439","0.00240680399326989"
"0.121620947524436","6908.32920541783","0.00242805809669901"
"0.12262036847904","6969.13124292697","0.00244738493072544"
"0.123637966723658","7028.7613760042","0.00247043252906095"
"0.124637387678262","7084.68567416002","0.00249574541372768"
"0.125618640509412","7138.83740648909","0.00251133515550865"
"0.126618070630577","7199.90069657859","0.00253272561152928"
"0.127617491585181","7259.0056900153","0.00255731261916473"
"0.128635089829799","7318.30695219725","0.002575796416055"
"0.129625426722676","7371.27799849509","0.00259616250890916"
"0.130606679553826","7430.87871321453","0.00261940632893623"
"0.131597025613264","7491.70007024221","0.00264200190124359"
"0.132614623857882","7552.15699089729","0.00266266676668796"
"0.133614044812486","7609.47800242811","0.0026800081809418"
"0.134595297643636","7666.32217311478","0.00270208756129558"
"0.135594727764801","7728.15165774667","0.00272416207191395"
"0.136603232781131","7788.64985191864","0.00274357341017251"
"0.137602662902296","7845.35878597548","0.0027631342779537"
"0.138592999795173","7896.52565268895","0.00278210361610995"
"0.139574252626323","7956.0078158173","0.0028027787939352"
"0.1405645895192","8014.81906475609","0.00282345053430016"
"0.141591271825545","8074.79475376735","0.00284630735358957"
"0.14259070194671","8127.91289185413","0.0028641308716491"
"0.14357195477786","8184.51820303875","0.00288418616080202"
"0.144571375732464","8242.82538817544","0.00290574104200653"
"0.145588973977082","8303.32358234741","0.00292658923866638"
"0.146588394931686","8357.5429329914","0.00294694387331957"
"0.147569656929397","8411.14581536174","0.00296510426248754"
"0.148569077884001","8471.13379861207","0.00298791467606303"
"0.149568498838605","8531.6126732655","0.00300898029208623"
"0.150586097083223","8587.32138315753","0.00302828163161551"
"0.151567349914373","8637.60657729727","0.00304929568573437"
"0.152557695973811","8695.19015864836","0.00306749646506074"
"0.153548032866688","8753.92676399276","0.00308824096500184"
"0.154565631111306","8813.85591052751","0.00311059906609415"
"0.155565061232471","8866.29523098532","0.00312893906256228"
"0.156546304897061","8919.47044946781","0.00315020347837227"
"0.157536641789938","8976.96445850563","0.00316966867017538"
"0.15854516513939","9035.84332575934","0.00319172141021191"
"0.15955367015572","9090.49560925078","0.00321086634529799"
"0.16053491382031","9142.84096659566","0.00322892045965198"
"0.161534343941475","9200.94880942733","0.00325010524096525"
"0.162533774062639","9260.98333515416","0.00327300073168292"
"0.16354227907897","9317.07580093734","0.00329380023098866"
"0.164541709200134","9368.00292998883","0.00331336253104497"
"0.165532046093011","9423.63963076627","0.00333415286378994"
"0.166522382985889","9480.14746619822","0.00335507754394125"
"0.167539981230507","9541.00921858287","0.00337607211911846"
"0.168539411351671","9592.39386895996","0.00339904208814241"
"0.169529748244548","9645.20816370958","0.00342003494458948"
"0.170520085137425","9701.12675382583","0.00344166516346534"
"0.17151951525859","9760.88729365326","0.00346437102095701"
"0.172528020274921","9815.47634962946","0.00348391412852669"
"0.173527450396085","9868.08515495453","0.00350558960729638"
"0.174517787288962","9924.01252667012","0.00352863749208691"
"0.175517217410127","9981.5934735414","0.00354984375752699"
"0.176525722426458","10038.4894556642","0.00357174610867583"
"0.177525152547622","10089.9944139522","0.00359236628713644"
"0.178515489440499","10144.7819340735","0.00361292860168216"
"0.179487658209923","10199.1040294298","0.00363554880912159"
"0.180514331349707","10262.2261654845","0.00365921772840455"
"0.181513761470872","10316.0213648804","0.00367867117555167"
"0.182513191592036","10369.7708999597","0.00370003269961485"
"0.183494435256626","10423.5257039986","0.00372188348885934"
"0.184502958606078","10483.8157742662","0.00374403534233423"
"0.185502370394121","10538.9369951624","0.00376680250120107"
"0.186501800515286","10590.4779580078","0.00378327796191681"
"0.187492137408163","10644.8729406386","0.00380608064120665"
"0.188473399405874","10699.5559597277","0.00382435131555892"
"0.189490997650492","10757.1913525149","0.00384459767021297"
"0.190499502666823","10808.2010286002","0.00386470051089991"
"0.1914898395597","10858.2903930746","0.00388646708236729"
"0.192462008329123","10911.5806505085","0.00390436078190774"
"0.193479606573741","10971.9752218082","0.00392707580596018"
"0.194488111590072","11024.6288132899","0.00394754674135319"
"0.195487541711237","11073.9787671","0.00396575410914512"
"0.196477878604114","11124.4185173881","0.00398669884114812"
"0.197468215496991","11178.9768377666","0.00400750120500411"
"0.198476738846443","11233.3287905607","0.00402768396664279"
"0.199485243862773","11283.366343599","0.00404598443231758"
"0.200466487527363","11331.839015635","0.00406679825437453"
"0.201456842753362","11385.6210426319","0.00408592342406394"
"0.202474422664858","11440.8599369592","0.00410636284940429"
"0.20348294601431","11490.1914494107","0.00412467849719536"
"0.204473282907187","11537.5269043322","0.00414225967430444"
"0.205454526571777","11584.1387554681","0.00416197837880395"
"0.206463049921229","11643.0509927993","0.00418370284138277"
"0.207462461709272","11691.274267414","0.00420231153266358"
"0.208461891830437","11736.4810626556","0.00422005684850151"
"0.209443153828148","11784.163390751","0.00423585713472525"
"0.210424397492737","11836.3287253094","0.0042580877633318"
"0.211441995737356","11888.5353333847","0.00427608544604603"
"0.212450519086808","11937.0150307002","0.00429576118229192"
"0.213440855979685","11981.791527574","0.00431208825930513"
"0.214422099644274","12030.863104685","0.00433305648062011"
"0.215430622993726","12084.3307504255","0.00435107507455111"
"0.216439128010057","12133.4804837706","0.00437103955746137"
"0.217438558131222","12176.9002235465","0.00438546772411929"
"0.218410726900645","12219.7517938451","0.00440119038103148"
"0.219419231916976","12274.6227391601","0.00442415949069037"
"0.22041866203814","12322.5553428367","0.00444082401172207"
"0.221427167054471","12368.0194389389","0.00445946507242061"
"0.222408410719061","12409.5362061378","0.00447723846085091"
"0.223398765945059","12459.5561959775","0.00449488609552559"
"0.22440727096139","12507.7127304373","0.00451253802702564"
"0.22541577597772","12555.6585065129","0.00452913236657642"
"0.226415206098885","12598.4187481783","0.00454452703248592"
"0.227387374868308","12644.5063378336","0.00456432508502713"
"0.228395879884639","12699.3263498725","0.00458260721758037"
"0.229395310005804","12749.0258113363","0.0046019280360513"
"0.230394740126968","12795.0422700369","0.00461807407348923"
"0.231366908896392","12838.6165659612","0.00463418115304387"
"0.232375413912722","12892.5382203875","0.0046544687572214"
"0.233374844033887","12942.8989362816","0.00467065461190769"
"0.234392442278505","12990.2124372048","0.00468760873896884"
"0.235391854066548","13033.546995467","0.00470214862308619"
"0.236373116064259","13078.8618043804","0.00471568505525384"
"0.237372527852302","13129.7625886339","0.00473472543425609"
"0.238390126096921","13179.4128731414","0.00475004161148897"
"0.239398649446373","13221.2879295934","0.00476606934300191"
"0.240379893110962","13263.2701215573","0.00477693200397386"
"0.241388416460415","13313.5438996179","0.0047952768701774"
"0.242387828248458","13362.4240378633","0.00481292221321189"
"0.243405426493076","13406.8817626811","0.00482807797563123"
"0.244386688490787","13444.0375876479","0.00484165938123767"
"0.24538610027883","13491.0788589915","0.00485855793602413"
"0.246367362276541","13536.4762149387","0.00487621445080456"
"0.247394053749447","13582.1554602247","0.00489101271735372"
"0.248384390642324","13621.2256738476","0.00490341335535049"
"0.249374727535201","13662.5729561792","0.00491987134230976"
"0.250374139323244","13709.3665864215","0.00493501621943818"
"0.251391737567862","13758.2467246668","0.00495172055771824"
"0.252400260917314","13798.6438379499","0.00496637616966536"
"0.253390597810191","13836.7902273222","0.00497682776767761"
"0.254380934703068","13880.1344453438","0.00499520901366922"
"0.255380364824233","13927.3838405917","0.00500948994244471"
"0.256397963068851","13971.9065492447","0.00502600693913895"
"0.257388299961728","14006.0704833164","0.00504175738218849"
"0.258378636854605","14049.9091053808","0.00505508040536312"
"0.259368973747482","14092.9275260668","0.00507012846069337"
"0.260395646887267","14140.7529942315","0.00508745956256634"
"0.261395077008431","14177.6515183376","0.00510087024097837"
"0.262394507129596","14214.8486168212","0.00511292541421598"
"0.263375750794185","14256.0791038817","0.00512745613177256"
"0.264384274143638","14305.5537564024","0.00514742949478856"
"0.265392779159968","14348.7302458765","0.00516301780429441"
"0.266392209281133","14391.0303317366","0.0051785780412079"
"0.26738254617401","14438.73900463","0.00519561237567581"
"0.268372883066887","14490.7181692824","0.00521597417170461"
"0.269390481311505","14541.7392614468","0.00523312423400229"
"0.27038991143267","14582.7001534075","0.00525077501968224"
"0.271380248325547","14626.7679752147","0.00526583453321345"
"0.272370585218424","14673.1989254042","0.00528443520375359"
"0.273379090234755","14724.0619487805","0.00530383966709157"
"0.274387613584207","14769.2046383468","0.00532180956366846"
"0.27538702537225","14808.5181022714","0.00533396155870424"
"0.276368287369961","14853.7134814338","0.00535246025125577"
"0.277367717491125","14905.9025263104","0.00537105461978537"
"0.278385315735744","14952.1815548313","0.00539004486915839"
"0.279384727523787","14991.3246557287","0.0054034612766709"
"0.280375064416664","15032.6122231848","0.00542007509516332"
"0.281365419642662","15078.475003897","0.00543716500190593"
"0.282373924658993","15127.8802817829","0.00545512344028185"
"0.283382429675324","15167.9419379713","0.00547239725114998"
"0.284381859796488","15206.6178577838","0.00548832930668485"
"0.285354028565912","15246.7585483661","0.0055035314748181"
"0.286362533582242","15295.7001578069","0.00552732213748634"
"0.287371038598573","15339.6239613849","0.00554308804910718"
"0.288370468719738","15378.5545475782","0.00555488369409288"
"0.289351730717449","15417.3604350609","0.00557242218940335"
"0.290351142505492","15466.4829454481","0.00559186503771458"
"0.291359665854944","15511.6958878091","0.00560965332180614"
"0.292377264099562","15551.8084772736","0.00562509210178937"
"0.293376675887605","15590.5511372411","0.00564155008874863"
"0.294348844657029","15630.8885356487","0.00565796396163417"
"0.295357368006481","15678.0632873023","0.00567780841988929"
"0.296374966251099","15720.0955343824","0.00569517275054506"
"0.297374378039142","15758.3604753458","0.00570908300651927"
"0.2983374719134","15794.5248577471","0.00572568422099062"
"0.29934597692973","15842.9430838672","0.00574403452983962"
"0.300354481946061","15887.4218845235","0.00576170995065165"
"0.301372080190679","15926.2330409658","0.00577867668173386"
"0.30235334218839","15959.7699688446","0.00579309854638125"
"0.303343679081267","16004.8617251348","0.00581131708591912"
"0.304334015974144","16048.4974922544","0.00582907729741831"
"0.305351614218763","16088.7769321064","0.00584810134848418"
"0.30634195111164","16124.3441657525","0.00585865034120465"
"0.307314119881063","16161.2233703401","0.00587351792986967"
"0.308322624897394","16207.9625546664","0.00589197823744795"
"0.309340223142012","16249.6294872141","0.00591247581315821"
"0.310348728158343","16286.7475513037","0.00592714803949673"
"0.311329990156054","16319.3237722147","0.00594082282944106"
"0.312329401944097","16361.5702903188","0.00595857043691918"
"0.313310663941808","16403.6885970725","0.00597517107848049"
"0.314337355414713","16443.1232470679","0.00599263165802438"
"0.315327673974469","16475.9471090804","0.00600503000438096"
"0.31630893597218","16514.781097681","0.00602167476001599"
"0.317317440988511","16558.4836049556","0.00604098870356633"
"0.318325982671084","16598.7279184102","0.00606177101557062"
"0.319325394459127","16634.2248992616","0.00607373738775074"
"0.320306656456838","16664.4511641893","0.00608612141135611"
"0.321306068244882","16707.0032819504","0.00610378365523703"
"0.322305480032925","16749.2199426167","0.00612304546397297"
"0.32333217150583","16785.8075981062","0.00613936881707087"
"0.324313433503541","16815.3401166861","0.00615045004322626"
"0.32530378872954","16853.6068139693","0.00616968377936983"
"0.326303200517583","16893.663201198","0.00618572526072394"
"0.327311705533914","16932.040546633","0.0062005601935162"
"0.328320210550244","16964.5184136314","0.00621548220863581"
"0.329301472547955","16998.4645640395","0.00623052739941581"
"0.330300884335998","17035.6844946814","0.00624956691905299"
"0.331300332790285","17075.6337463982","0.0062666190137324"
"0.332326987596947","17109.702839197","0.00628228065572444"
"0.333317342822946","17139.0052798741","0.00629696491317398"
"0.334298604820657","17175.9459556571","0.00631204333273679"
"0.335307109836988","17216.3307747011","0.00632914527059041"
"0.336324708081606","17254.3550998426","0.00634634861352259"
"0.337324119869649","17281.4340395669","0.00635884893786778"
"0.33830538186736","17315.3064245405","0.00637446589287605"
"0.339295737093359","17350.69626988","0.00639164001739577"
"0.340304242109689","17391.7010698374","0.0064096826735488"
"0.341321840354307","17423.7099994311","0.00642326407915524"
"0.342312158914063","17455.9138805301","0.00643862322464175"
"0.343293420911774","17490.0936214806","0.00645473574684185"
"0.344301925928105","17534.6022795747","0.00647294741145915"
"0.345310430944435","17577.6883185756","0.00649343753933877"
"0.346309879398721","17617.0509594565","0.00651007198259293"
"0.347300197958477","17663.4072660516","0.00653166725395585"
"0.348299646412763","17714.5565695664","0.00655458021842999"
"0.349326301219426","17766.7245386046","0.00657745823539119"
"0.350334842902","17804.5802570387","0.00659782518761042"
"0.351325161461755","17845.679898269","0.00661728694195324"
"0.352297330231178","17887.3837135339","0.00663908731511347"
"0.353324021704084","17939.6026158483","0.00666175392826682"
"0.354323433492127","17981.9650510636","0.00668567979770647"
"0.355322881946414","18019.7522730229","0.00670399630486261"
"0.356313200506169","18060.7201902631","0.00672688520711473"
"0.3573217055225","18110.4960516411","0.00674835329244691"
"0.35833021053883","18157.1158062164","0.00677083141819435"
"0.359338752221404","18193.4874343621","0.00679273491516328"
"0.36032907078116","18234.8470109329","0.00681837550437767"
"0.361301239550583","18279.9106661052","0.00684034202145193"
"0.362327931023489","18331.6272609373","0.00686463512623257"
"0.36333643603982","18369.6392918397","0.00688367350004965"
"0.364326791265818","18407.3667989235","0.00690789098070392"
"0.365298960035241","18448.5384492684","0.00692845444106974"
"0.36631655827986","18498.2949911279","0.00695451268170938"
"0.367315970067903","18543.1812579935","0.00697959640235677"
"0.368333568312521","18580.6242412587","0.00700089318758449"
"0.369314830310232","18619.5934664891","0.00702422437639394"
"0.370314242098275","18665.8338559729","0.00704826253620306"
"0.371322747114606","18712.2990543998","0.00707294980309698"
"0.372331252130936","18751.484306974","0.00709443049245023"
"0.373312514128647","18787.5485791429","0.00711844745458756"
"0.374302869354646","18832.8756822953","0.00714506027215402"
"0.375311374370977","18881.0778810717","0.00717108012782043"
"0.376328972615595","18922.7483262591","0.00719619994180086"
"0.377328384403638","18957.0527659202","0.0072176118819483"
"0.378300553173061","18993.6632535679","0.00724170618694217"
"0.379299964961105","19041.2788415084","0.00726822905763104"
"0.380308506643678","19084.0610371722","0.0072939865204953"
"0.381326104888296","19124.2438794314","0.0073184852999833"
"0.382307330219764","19157.6631338791","0.00734194482064359"
"0.383297685445763","19202.5897961016","0.00736914601682971"
"0.384306190462094","19247.9010923753","0.00739617591291138"
"0.385314695478424","19289.5715375627","0.00742234816265065"
"0.386305050704423","19329.0237507568","0.00744681715081615"
"0.387286312702134","19369.8546750473","0.00747266627928814"
"0.388294817718465","19417.8847544766","0.00750240546698851"
"0.389303322734795","19461.7418178996","0.00752789996414057"
"0.390311827751126","19497.6568028796","0.0075555526134448"
"0.391283996520549","19530.5719935252","0.00757705564628993"
"0.392283408308592","19574.8540863562","0.00760715232986048"
"0.393273763534591","19616.5737084999","0.00763465143927175"
"0.394300455007497","19658.3319696807","0.00766210070550882"
"0.395290773567252","19688.8989606627","0.00768643620563304"
"0.396272035564963","19727.5573172766","0.00771095503697274"
"0.397262390790962","19770.237646388","0.00774357939967666"
"0.39827998903558","19813.961229501","0.00777039961068062"
"0.399279400823623","19848.3253840377","0.0077993499012444"
"0.400260662821334","19883.2533172519","0.00782627552769726"
"0.401260074609377","19927.3597780962","0.00785806172300042"
"0.40225948639742","19971.4416504622","0.00788838184148983"
"0.403277084642039","20008.4490664002","0.00791481018202071"
"0.404249253411462","20036.1111043206","0.00794189450455698"
"0.405230515409173","20077.7920874272","0.00797346356695181"
"0.406220870635172","20118.7810805058","0.00800232448354803"
"0.407256618670122","20165.3815155626","0.00803819037130557"
"0.408256067124408","20197.5379760252","0.00806546948325828"
"0.409237292455876","20229.9754476666","0.00809482138376595"
"0.410218554453587","20269.6015365277","0.0081259985756877"
"0.411236152698205","20313.3497081189","0.00815825627596066"
"0.412235564486248","20346.7882820851","0.00818924097010616"
"0.413216826483959","20380.1618722162","0.00822004978086682"
"0.414207181709958","20429.6532097756","0.00825418949064865"
"0.415206593498001","20484.7243755556","0.00829846397918598"
"0.416224191742619","20537.129447776","0.00833663296533793"
"0.417223603530662","20577.4791404226","0.00837311072102711"
"0.418195772300086","20627.0618066152","0.00841583835243387"
"0.419186127526084","20679.6389981826","0.00846035117155132"
"0.42021281899899","20737.578234307","0.00850783739381976"
"0.421212230787033","20779.3540586864","0.00854881593084887"
"0.422193492784744","20825.0464763715","0.00859544393386487"
"0.4231838113445","20873.3979623366","0.00864281099084325"
"0.424192353027073","20930.6820911502","0.00869506783508439"
"0.425200858043404","20976.8206140816","0.008739665444889"
"0.426200269831447","21018.0625172212","0.00878802650080128"
"0.427181531829158","21067.7575878853","0.00883831539902631"
"0.428180943617201","21121.9242489333","0.0088898549598869"
"0.429198541861819","21174.8755366326","0.00894509437383981"
"0.43020704687815","21216.6847310896","0.00899612977385785"
"0.431188308875861","21261.347945332","0.00904800792455702"
"0.432169570873572","21313.7986818689","0.00910124616371101"
"0.433196262346478","21374.9432017523","0.00916385434670594"
"0.434195674134521","21421.0307914076","0.00921934526817008"
"0.435204179150852","21466.0066305865","0.00927866552039746"
"0.436176347920275","21514.0858869721","0.00933522663783194"
"0.437184852936606","21573.0437886198","0.00939800268347104"
"0.438193357952936","21628.4100161376","0.00946225053502437"
"0.43920189963551","21677.8188066632","0.00952434424479587"
"0.440192218195266","21731.7782219668","0.00959426677037823"
"0.441182573421264","21789.2608149255","0.00966106235291662"
"0.442191078437595","21848.2064223341","0.00973364661858366"
"0.443199583453926","21896.8020367609","0.00980498652362565"
"0.444189938679924","21947.0380539444","0.00987665527903541"
"0.445171164011392","21999.306133215","0.00994612978895994"
"0.44618876225601","22063.3011602441","0.0100277786374121"
"0.447197267272341","22116.5000890448","0.0101015499726994"
"0.448205808954915","22165.3591514518","0.0101765656686117"
"0.449187034286383","22215.6355639922","0.0102558758982465"
"0.450177389512381","22274.1895120703","0.0103371248554849"
"0.451194987756999","22333.5232661699","0.010418855057164"
"0.45220349277333","22384.4582986607","0.0105016726421148"
"0.453202904561373","22435.2405313231","0.0105811169327009"
"0.454175073330797","22488.1338604668","0.0106657414759443"
"0.455192671575415","22556.171935832","0.0107560172039047"
"0.456210269820033","22618.2297420467","0.0108531174363612"
"0.457218774836364","22676.8223291619","0.0109461740696964"
"0.458181887043743","22736.8024089728","0.0110457733357839"
"0.459190392060073","22808.5586134985","0.0111516196130386"
"0.460198897076404","22875.5288463839","0.011259782738529"
"0.461207402092735","22937.1598668707","0.0113686425226381"
"0.462197757318733","22995.1412546719","0.0114795475956199"
"0.463178982650201","23066.3846137961","0.0115978821661089"
"0.464178431104487","23138.3111813489","0.0117196014891635"
"0.465214179139438","23209.3191936108","0.0118441509878571"
"0.466213627593724","23271.7317764389","0.0119708443159516"
"0.467185796363147","23338.9426251462","0.0121014277032745"
"0.46818520815119","23409.952393728","0.0122373322791266"
"0.469202806395809","23483.0293507943","0.012372576862603"
"0.470211311412139","23546.8136194393","0.012506514065349"
"0.471183480181563","23604.8371589173","0.0126398084630207"
"0.472173835407561","23679.6300404946","0.0127829271222017"
"0.473182340423892","23751.3195048653","0.0129261156764087"
"0.474209031896798","23819.8493497935","0.0130667272812181"
"0.475199350456553","23877.1615797249","0.0132046633961016"
"0.476180612454264","23948.6156972333","0.0133536314668765"
"0.477180024242307","24018.4961521399","0.0135012967402013"
"0.478197622486925","24091.3166865056","0.0136517222941391"
"0.479197070941212","24150.9595529018","0.0137995479822775"
"0.480160146482348","24213.1438141471","0.0139484621995077"
"0.481159558270391","24284.3889295911","0.0141033805140448"
"0.482177156515009","24356.9144022189","0.0142584684099562"
"0.483176604969295","24421.083304915","0.0144134245365565"
"0.484157830300763","24477.6455862628","0.0145651895541874"
"0.485139092298474","24548.1653416014","0.0147269770602043"
"0.486138504086517","24616.3527041553","0.014886238032908"
"0.487156102331135","24685.474428879","0.0150513094593221"
"0.488155550785421","24744.0020321591","0.0152100101259984"
"0.489127719554845","24807.148756692","0.0153762388307103"
"0.4901180381146","24876.3301962912","0.0155420504569069"
"0.491144729587506","24948.3990257533","0.0157151827277014"
"0.492153234603837","25008.6285029855","0.0158827417295455"
"0.493134496601548","25062.8074582725","0.0160537828786636"
"0.494124851827546","25132.9531174793","0.0162272978533705"
"0.495115170387302","25200.6399288708","0.0164042285177857"
"0.49613276863192","25264.2169517713","0.0165790336859215"
"0.497114030629631","25316.6483687897","0.0167527170961825"
"0.498104349189387","25380.0111206664","0.0169305735832359"
"0.499094704415385","25444.4821103797","0.017113462512154"
"0.500112302660003","25509.5028282117","0.017295010831559"
"0.501111714448046","25564.6793731837","0.0174749401071674"
"0.502092976445758","25620.0754581392","0.0176579963258196"
"0.503074238443469","25680.7036199814","0.017845378015337"
"0.504082743459799","25748.7329137473","0.0180318625277187"
"0.505100341704417","25807.3360387817","0.0182191880720514"
"0.506090660264173","25855.3362607732","0.0184032549040289"
"0.507081015490171","25914.4118358521","0.0185950331052575"
"0.50807137071617","25975.8531737932","0.0187862040218347"
"0.509088968960788","26036.1300716618","0.0189817416588006"
"0.510088380748831","26085.0541179039","0.0191733239247926"
"0.511078699308587","26137.4504085249","0.0193637958911108"
"0.51205086807801","26191.4660260642","0.0195605492431993"
"0.513068466322629","26254.960501931","0.0197610288022423"
"0.514095157795534","26306.8158460327","0.0199563888370932"
"0.515094606249821","26355.3394513449","0.0201554040380526"
"0.516066775019244","26405.6070822859","0.0203538967450479"
"0.517084336597619","26466.9096709574","0.0205577793897782"
"0.518092878280193","26518.8703942512","0.0207618178660417"
"0.519092290068236","26562.7660967113","0.0209620682610654"
"0.520073552065947","26610.2534733014","0.0211650388329987"
"0.521054814063658","26663.34702291","0.0213700375065031"
"0.522072375642033","26719.3929462167","0.0215797386256846"
"0.523089973886651","26764.4811898671","0.0217826312818513"
"0.52408032911265","26807.5707415078","0.021992442399762"
"0.525052497882073","26853.5792967691","0.0222029868425347"
"0.526070096126692","26909.3248893783","0.0224169137462328"
"0.527078601143022","26956.325765365","0.0226295596230628"
"0.528087106159353","26998.4809548359","0.0228390819943092"
"0.529077461385351","27039.7509590934","0.0230509601716744"
"0.530067779945107","27089.7006961383","0.0232686453652898"
"0.531076321627681","27139.801476692","0.0234895755214191"
"0.532102976434343","27180.5621481877","0.0237065640564157"
"0.533093331660342","27219.480440142","0.0239261008953074"
"0.534065500429765","27261.4406781076","0.0241450533659498"
"0.535083098674384","27310.972411024","0.0243698357692443"
"0.536091603690714","27354.7118010158","0.0245930346491651"
"0.537100108707045","27389.9839729242","0.0248158577000942"
"0.538072277476468","27425.1648161994","0.0250361691133713"
"0.539071689264512","27473.922012054","0.0252679524774568"
"0.54008928750913","27516.4723734953","0.025497943778911"
"0.541106885753748","27552.6051421389","0.0257243005390184"
"0.542088147751459","27587.0518437094","0.0259521124906486"
"0.54306940974917","27627.6368832183","0.026186632073125"
"0.544087007993788","27671.0583793141","0.0264205214545483"
"0.545213614979128","19766.6003079414","-0.122435983109075"
"0.546231213223746","20076.5749577587","-0.122327909357552"
"0.547230661678033","20359.8096375862","-0.122240341202481"
"0.548211887009501","20632.2288996668","-0.122152278053127"
"0.549193149007212","20885.5850659004","-0.122069824838967"
"0.550219840480117","21118.0937153013","-0.121993036559365"
"0.55121925226816","21309.7644151322","-0.121927614815123"
"0.552209607494159","21479.6093279639","-0.12187415543269"
"0.55319086949187","21637.2039097165","-0.121822006868448"
"0.554199374508201","21784.0269817189","-0.121778209041071"
"0.555207879524531","21914.0965185008","-0.1217359053631"
"0.55622547776915","22029.9978229077","-0.121700513271952"
"0.557206739766861","22139.6132585073","-0.121668045313692"
"0.558197058326616","22251.7490131173","-0.121633844875445"
"0.559214656571234","22357.2406096669","-0.121599305274449"
"0.560223161587565","22451.3003201958","-0.121572364752335"
"0.561204423585276","22542.5095235791","-0.121543746749599"
"0.562194778811275","22638.9016268927","-0.121515147079985"
"0.563221433617937","22737.8035112976","-0.121485282424984"
"0.564229975300511","22823.994908818","-0.121459680220743"
"0.565229387088554","22905.0490707247","-0.121434188015231"
"0.566201555857977","22982.4887263431","-0.121407329992164"
"0.567200967646021","23072.0153752928","-0.121381920285699"
"0.568209472662351","23153.1362773544","-0.121356473912991"
"0.56922707090697","23225.9427611611","-0.121334602498985"
"0.570199239676393","23294.569203682","-0.121314619396498"
"0.571189594902392","23372.8431112377","-0.121289383854688"
"0.572198099918722","23449.4133885214","-0.121266384953706"
"0.57321569816334","23517.2933950985","-0.121242698560667"
"0.574206053389339","23580.0133339034","-0.121224631269382"
"0.575178222158762","23645.6891590462","-0.121203383181508"
"0.576186727175093","23717.8774182593","-0.121182254258925"
"0.577195232191424","23785.5343722131","-0.121161317834117"
"0.578203737207754","23843.2312361957","-0.121143507206534"
"0.57916681274889","23898.8907691314","-0.121124569091975"
"0.580166261203176","23965.5150070029","-0.12110164352348"
"0.581165672991219","24029.5855557863","-0.121084007060551"
"0.582192364464125","24089.8817731734","-0.121063217300716"
"0.583182683023881","24141.0539088465","-0.121046332495771"
"0.584173038249879","24200.1681229625","-0.121030025184155"
"0.585163356809635","24260.3888185954","-0.121008089604223"
"0.586180955054253","24317.9486896282","-0.12098993064733"
"0.587171310280252","24366.8990806683","-0.120973385005133"
"0.588152572277963","24421.7647570237","-0.120955675209718"
"0.589151984066006","24489.082741243","-0.120933611297936"
"0.590305870736209","17809.9932348718","-0.120420898054176"
"0.591332562209114","14997.1942767274","-0.113099428465751"
"0.592331973997157","15292.0083734444","-0.113004664560472"
"0.593331385785201","15578.1497626534","-0.112909387327789"
"0.594285404764292","15859.1223024909","-0.112818785041101"
"0.595284816552335","16147.3589813024","-0.112720730340504"
"0.596284228340378","16423.222386644","-0.112627506417435"
"0.597283676794664","16685.9906710501","-0.112536849131382"
"0.598264938792375","16934.8717342601","-0.112451187620951"
"0.599255257352131","17175.6667007981","-0.112361181160714"
"0.600254705806417","17401.5118726199","-0.112277829623598"
"0.601272304051035","17605.7543100657","-0.112200546349714"
"0.602271715839078","17793.6260900222","-0.112077329439793"
"0.603234791380214","17970.4822317668","-0.129369725509891"
"0.604243296396545","18143.4832514013","-0.0917100197246929"
"0.605251801412875","18301.2640030599","-0.0672199988855034"
"0.606260343095449","18438.966505988","-0.0701301527671575"
"0.607223418636585","18560.679472838","-0.0752735879330889"
"0.608241016881203","18684.8196737456","-0.0751593221697634"
"0.609231335440959","18786.5913848148","-0.0750485442828123"
"0.610248933685577","18872.5035274763","-0.0753795396257925"
"0.611230195683288","18936.8146920816","-0.0753519528611439"
"0.612220550909286","18994.2375701648","-0.0753276431419718"
"0.613219962697329","19040.7800466659","-0.0753084850299546"
"0.614246654170235","19080.4799009614","-0.0752901519084071"
"0.615246065958278","19108.2701502322","-0.0752759070729646"
"0.616218234727702","19134.7905802385","-0.0752644076224739"
"0.617226776410276","19166.5887514481","-0.075249695292432"
"0.618226151532076","19194.1366285771","-0.0752387412523074"
"0.619243786442937","19213.6194848725","-0.0752296617738609"
"0.620225048440648","19227.007911226","-0.0752237493421618"
"0.62121533033416","19254.1939864622","-0.0752088445143437"
"0.622223872016734","19276.2568766436","-0.0752024875044471"
"0.623241433595109","19295.0459865911","-0.0751930596966912"
"0.624240882049395","19306.9959869728","-0.0751872114309176"
"0.624649710659906","19187.9333068035","-0.0752231764321135"
"0.624649710659906","19018.0357043757","-0.0752804170208653"
"0.624649710659906","18905.376566445","-0.0753171749295681"
"0.624640690764104","18820.642914415","-0.0753457058499765"
"0.624631597535817","18753.9431547892","-0.0753681043412272"
"0.624631597535817","18699.7238041452","-0.0753860478839419"
"0.624631597535817","18653.6871477661","-0.0754012918745087"
"0.624631597535817","18613.9574360328","-0.0754132084035146"
"0.624631597535817","18578.7520042794","-0.0754265549160012"
"0.624631597535817","18548.2447281728","-0.0754362210543372"
"0.624631597535817","18519.9416335006","-0.0754467075998624"
"0.624631597535817","18495.1055142476","-0.0754553150004289"
"0.624631597535817","18471.9712689468","-0.0754629369957123"
"0.624631597535817","18450.285987537","-0.0754701969118452"
"0.624631597535817","18430.4167408707","-0.0754769297507335"
"0.624631597535817","18412.3898737459","-0.075483735922108"
"0.624631597535817","18394.7248085139","-0.0754895154386759"
"0.624631597535817","18378.4103532603","-0.0754965553573501"
"0.624631597535817","18363.4394827058","-0.0755020002944498"
"0.624631597535817","18348.5564281446","-0.0755067989890148"
"0.624631597535817","18335.0257398818","-0.0755107543599887"
"0.624631597535817","18322.0816624549","-0.0755155759709557"
"0.624631597535817","18309.855919854","-0.0755194259264807"
"0.624631597535817","18297.9972481055","-0.0755251962764878"
"0.624631597535817","18286.8375916644","-0.0755262366811356"
"0.624631597535817","18276.0379807963","-0.0755345553350378"
"0.624631597535817","18265.6282729389","-0.0755378369637948"
"0.624631597535817","18256.221423726","-0.0755378369637948"
"0.624631597535817","18246.1436603237","-0.075543158152324"
"0.624631597535817","18237.8432926276","-0.0755473931034015"
"0.624631597535817","18228.6524707586","-0.0755501568214748"
"0.624631597535817","18220.6436521606","-0.0755528059575384"
"0.624631597535817","18211.7584299486","-0.0755562663342305"
"0.624631597535817","18203.8444526235","-0.0755564909149695"
"0.624631597535817","18196.3063277502","-0.0755610375291133"
"0.624631597535817","18188.7875223955","-0.075565607059659"
"0.624631597535817","18181.9203117117","-0.0755693470164547"
"0.624631597535817","18174.8985448796","-0.0755702453394105"
"0.624631597535817","18167.8346263706","-0.0755731144729327"
"0.624631597535817","18161.6330609168","-0.0755752181986303"
"0.624631597535817","18155.1715601226","-0.0755804018887479"
"0.625158564781579","18304.7836680753","-0.0755302699678761"
"0.626176126359955","18613.8678637195","-0.0754250882662774"
"0.627184668042528","18888.7336793762","-0.0753379005234776"
"0.628184043164328","19112.5678649491","-0.0752633993007888"
"0.629165305162039","19276.5326188629","-0.0752042108178725"
"0.630173846844613","19382.0207027727","-0.0751664079212415"
"0.631191408422988","19439.1502754379","-0.0751440781791966"
"0.632199950105562","19465.6443606462","-0.0751343937077391"
"0.633172118874985","19475.7554941261","-0.0751284675261988"
"0.634171567329272","19494.1564573828","-0.0751215284396931"
"0.635170942451072","19504.1990943878","-0.0751190534682842"
"0.636188577361933","19511.7354629412","-0.0751149193493752"
"0.637178932587931","19513.3688404184","-0.0751132097857909"
"0.638169214481444","19521.0667903997","-0.0751085852558805"
"0.63916866293573","19534.2391894095","-0.0751058490374896"
"0.640195317742393","19545.8080683798","-0.0751008486785875"
"0.641194766196679","19548.7095088017","-0.0750952662430762"
"0.64217602819439","19552.388998925","-0.0750941570892226"
"0.643175476648676","19564.5427324114","-0.0750872821686423"
"0.644193038227051","19576.1397124996","-0.0750832030490979"
"0.645201579909625","19580.4655283344","-0.0750800864184349"
"0.646173748679048","19577.6958119026","-0.0750794447591807"
"0.647182217029136","19591.2370380846","-0.0750732939969015"
"0.648181665483422","19596.9679098138","-0.0750687290496362"
"0.649208320290085","19606.848965391","-0.0750661028299745"
"0.650207768744371","19604.7800205865","-0.0750647690953819"
"0.651189030742082","19608.6052852589","-0.0750630778649191"
"0.652179385968081","19614.7084968001","-0.0750572204325847"
"0.653196947546456","19626.242249373","-0.075053540058434"
"0.65420548922903","19626.6883546195","-0.0750535538082752"
"0.655195844455028","19624.4420215084","-0.0750500475987792"
"0.656195219576828","19629.9182268567","-0.0750496992694698"
"0.657194668031114","19635.8440500912","-0.0750449922405125"
"0.658212229609489","19638.5259505296","-0.0750437685046492"
"0.659202584835488","19632.255888601","-0.0750459134798702"
"0.660192940061487","19635.3557931679","-0.075042095607308"
"0.661183295287485","19637.2403243862","-0.0750413622824461"
"0.66220085686586","19643.6368413454","-0.0750385252318866"
"0.663209398548434","19641.7048894906","-0.0750387543959059"
"0.664190660546145","19633.3395379595","-0.0750416831120731"
"0.665180942439658","19634.7990397698","-0.0750397673008714"
"0.666198577350519","19641.9876569894","-0.0750383098177084"
"0.667207119033093","19640.1400084883","-0.0750392631400289"
"0.668206494154893","19629.6653167957","-0.0750423156047665"
"0.669196849380891","19627.5840777522","-0.0750426960170386"
"0.670178111378602","19628.5535663193","-0.0750447905761754"
"0.671204766185265","19631.2811310742","-0.0750419351924944"
"0.672213307867839","19622.1482677608","-0.075045093072681"
"0.673203663093837","19614.9333057432","-0.0750473938794352"
"0.674184851759062","19609.149744418","-0.0750506159255472"
"0.675202486669923","19611.8562333345","-0.0750523300724119"
"0.67620193512421","19607.8272355574","-0.0750551671229714"
"0.676538091240905","19603.1062477523","-0.0750568950196772"